{
 "cells": [
  {
   "cell_type": "code",
   "execution_count": 2,
   "metadata": {},
   "outputs": [],
   "source": [
    "filename= 'Lending-company.csv'\n",
    "\n",
    "with open(filename, mode = 'r') as output_File:\n",
    "    output_File.read()"
   ]
  },
  {
   "cell_type": "code",
   "execution_count": 3,
   "metadata": {},
   "outputs": [
    {
     "name": "stdout",
     "output_type": "stream",
     "text": [
      "<_io.TextIOWrapper name='Lending-company.csv' mode='r' encoding='cp1252'>\n"
     ]
    }
   ],
   "source": [
    "print(output_File)"
   ]
  },
  {
   "cell_type": "code",
   "execution_count": 4,
   "metadata": {},
   "outputs": [
    {
     "ename": "RuntimeError",
     "evalue": "The current Numpy installation ('C:\\\\Users\\\\12016\\\\anaconda3\\\\lib\\\\site-packages\\\\numpy\\\\__init__.py') fails to pass a sanity check due to a bug in the windows runtime. See this issue for more information: https://tinyurl.com/y3dm3h86",
     "output_type": "error",
     "traceback": [
      "\u001b[1;31m---------------------------------------------------------------------------\u001b[0m",
      "\u001b[1;31mRuntimeError\u001b[0m                              Traceback (most recent call last)",
      "\u001b[1;32m<ipython-input-4-7dd3504c366f>\u001b[0m in \u001b[0;36m<module>\u001b[1;34m\u001b[0m\n\u001b[1;32m----> 1\u001b[1;33m \u001b[1;32mimport\u001b[0m \u001b[0mpandas\u001b[0m \u001b[1;32mas\u001b[0m \u001b[0mpd\u001b[0m\u001b[1;33m\u001b[0m\u001b[1;33m\u001b[0m\u001b[0m\n\u001b[0m",
      "\u001b[1;32m~\\anaconda3\\lib\\site-packages\\pandas\\__init__.py\u001b[0m in \u001b[0;36m<module>\u001b[1;34m\u001b[0m\n\u001b[0;32m      9\u001b[0m \u001b[1;32mfor\u001b[0m \u001b[0mdependency\u001b[0m \u001b[1;32min\u001b[0m \u001b[0mhard_dependencies\u001b[0m\u001b[1;33m:\u001b[0m\u001b[1;33m\u001b[0m\u001b[1;33m\u001b[0m\u001b[0m\n\u001b[0;32m     10\u001b[0m     \u001b[1;32mtry\u001b[0m\u001b[1;33m:\u001b[0m\u001b[1;33m\u001b[0m\u001b[1;33m\u001b[0m\u001b[0m\n\u001b[1;32m---> 11\u001b[1;33m         \u001b[0m__import__\u001b[0m\u001b[1;33m(\u001b[0m\u001b[0mdependency\u001b[0m\u001b[1;33m)\u001b[0m\u001b[1;33m\u001b[0m\u001b[1;33m\u001b[0m\u001b[0m\n\u001b[0m\u001b[0;32m     12\u001b[0m     \u001b[1;32mexcept\u001b[0m \u001b[0mImportError\u001b[0m \u001b[1;32mas\u001b[0m \u001b[0me\u001b[0m\u001b[1;33m:\u001b[0m\u001b[1;33m\u001b[0m\u001b[1;33m\u001b[0m\u001b[0m\n\u001b[0;32m     13\u001b[0m         \u001b[0mmissing_dependencies\u001b[0m\u001b[1;33m.\u001b[0m\u001b[0mappend\u001b[0m\u001b[1;33m(\u001b[0m\u001b[1;34mf\"{dependency}: {e}\"\u001b[0m\u001b[1;33m)\u001b[0m\u001b[1;33m\u001b[0m\u001b[1;33m\u001b[0m\u001b[0m\n",
      "\u001b[1;32m~\\anaconda3\\lib\\site-packages\\numpy\\__init__.py\u001b[0m in \u001b[0;36m<module>\u001b[1;34m\u001b[0m\n\u001b[0;32m    303\u001b[0m \u001b[1;33m\u001b[0m\u001b[0m\n\u001b[0;32m    304\u001b[0m     \u001b[1;32mif\u001b[0m \u001b[0msys\u001b[0m\u001b[1;33m.\u001b[0m\u001b[0mplatform\u001b[0m \u001b[1;33m==\u001b[0m \u001b[1;34m\"win32\"\u001b[0m \u001b[1;32mand\u001b[0m \u001b[0msys\u001b[0m\u001b[1;33m.\u001b[0m\u001b[0mmaxsize\u001b[0m \u001b[1;33m>\u001b[0m \u001b[1;36m2\u001b[0m\u001b[1;33m**\u001b[0m\u001b[1;36m32\u001b[0m\u001b[1;33m:\u001b[0m\u001b[1;33m\u001b[0m\u001b[1;33m\u001b[0m\u001b[0m\n\u001b[1;32m--> 305\u001b[1;33m         \u001b[0m_win_os_check\u001b[0m\u001b[1;33m(\u001b[0m\u001b[1;33m)\u001b[0m\u001b[1;33m\u001b[0m\u001b[1;33m\u001b[0m\u001b[0m\n\u001b[0m\u001b[0;32m    306\u001b[0m \u001b[1;33m\u001b[0m\u001b[0m\n\u001b[0;32m    307\u001b[0m     \u001b[1;32mdel\u001b[0m \u001b[0m_win_os_check\u001b[0m\u001b[1;33m\u001b[0m\u001b[1;33m\u001b[0m\u001b[0m\n",
      "\u001b[1;32m~\\anaconda3\\lib\\site-packages\\numpy\\__init__.py\u001b[0m in \u001b[0;36m_win_os_check\u001b[1;34m()\u001b[0m\n\u001b[0;32m    300\u001b[0m                    \u001b[1;34m\"See this issue for more information: \"\u001b[0m\u001b[1;33m\u001b[0m\u001b[1;33m\u001b[0m\u001b[0m\n\u001b[0;32m    301\u001b[0m                    \"https://tinyurl.com/y3dm3h86\")\n\u001b[1;32m--> 302\u001b[1;33m             \u001b[1;32mraise\u001b[0m \u001b[0mRuntimeError\u001b[0m\u001b[1;33m(\u001b[0m\u001b[0mmsg\u001b[0m\u001b[1;33m.\u001b[0m\u001b[0mformat\u001b[0m\u001b[1;33m(\u001b[0m\u001b[0m__file__\u001b[0m\u001b[1;33m)\u001b[0m\u001b[1;33m)\u001b[0m \u001b[1;32mfrom\u001b[0m \u001b[1;32mNone\u001b[0m\u001b[1;33m\u001b[0m\u001b[1;33m\u001b[0m\u001b[0m\n\u001b[0m\u001b[0;32m    303\u001b[0m \u001b[1;33m\u001b[0m\u001b[0m\n\u001b[0;32m    304\u001b[0m     \u001b[1;32mif\u001b[0m \u001b[0msys\u001b[0m\u001b[1;33m.\u001b[0m\u001b[0mplatform\u001b[0m \u001b[1;33m==\u001b[0m \u001b[1;34m\"win32\"\u001b[0m \u001b[1;32mand\u001b[0m \u001b[0msys\u001b[0m\u001b[1;33m.\u001b[0m\u001b[0mmaxsize\u001b[0m \u001b[1;33m>\u001b[0m \u001b[1;36m2\u001b[0m\u001b[1;33m**\u001b[0m\u001b[1;36m32\u001b[0m\u001b[1;33m:\u001b[0m\u001b[1;33m\u001b[0m\u001b[1;33m\u001b[0m\u001b[0m\n",
      "\u001b[1;31mRuntimeError\u001b[0m: The current Numpy installation ('C:\\\\Users\\\\12016\\\\anaconda3\\\\lib\\\\site-packages\\\\numpy\\\\__init__.py') fails to pass a sanity check due to a bug in the windows runtime. See this issue for more information: https://tinyurl.com/y3dm3h86"
     ]
    }
   ],
   "source": [
    "import pandas as pd"
   ]
  },
  {
   "cell_type": "code",
   "execution_count": null,
   "metadata": {},
   "outputs": [],
   "source": []
  }
 ],
 "metadata": {
  "kernelspec": {
   "display_name": "Python 3",
   "language": "python",
   "name": "python3"
  },
  "language_info": {
   "codemirror_mode": {
    "name": "ipython",
    "version": 3
   },
   "file_extension": ".py",
   "mimetype": "text/x-python",
   "name": "python",
   "nbconvert_exporter": "python",
   "pygments_lexer": "ipython3",
   "version": "3.8.5"
  }
 },
 "nbformat": 4,
 "nbformat_minor": 4
}
